Workbook

Sheet EDIFICACIONES
A1: ID | B1: DIRECCION PREDIO | C1: COORDENADAS | E1: CLASIFICACION DE LAS EDIFICACIONES | L1: DESCRIPCION DEL SISTEMA ESTRUCTURAL | U1: EVALUACION Y DIAGNOSTICO DE DAÑOS DE LA EDIFICACION | AC1: CONDICIONES DE LOS MOVIMIENTOS EN MASA EN EL PREDIO | AD1: FRAGILIDAD EDIFICACIONES | AK1: FRAGILIDAD PERSONAS | AL1: INTENSIDAD | AP1: 1-Se | AQ1: VULNERABILIDAD FISICA | AT1: VULNERABILIDAD PERSONAS | AV1: CALCULO DEL RIESGO
C2: LONGITUD | D2: LATITUD | E2: UBICACIÓN EN LA MANZANA | F2: NUMERO DE PISOS | G2: AREA TOTAL CONTRUIDA m2 | H2: ESTADO DE LA CONSTRUCCION | I2: CALIDAD EN LA CONSTRUCCION | J2: SERVICIOS PUBLICOS EN EL PREDIO | K2: PARAMETROS SOCIOECONOMICO (habitanntes) | L2: CIMENTACION | M2: SISTEMA DE ENTREPISOS | N2: SISTEMA ESTRUCTURAL | O2: SISTEMA DE CUBIERTA | P2: FECHA DE CONSTRUCCION | Q2: REFORMAS EN LA ESTRUCTUR | R2: IRREGULARIDAD EN PLANTA | S2: IRREGULARIDAD EN ALTURA | T2: TIPOLOGIA ESTRUCTURAL DE LA EDIFICACION | U2: CAUSA DE DAÑOS PRESENTES | V2: CONSECUENCIAS PRESENTES | W2: INUNDACIONES PREVIAS | X2: EVALUACION DE DAÑOS EN ELEMENTOS ESTRUCTURALES | AA2: SISTEMA DE RECOLECCION DE AGUAS SERVIDAS | AB2: REPARACION DE DAÑOS ANTERIORES | AC2: ZONAS O ESCENARIOS DE EXPOSICION | AD2: STIP | AE2: SALT | AF2: SCON | AG2: SED | AH2: SE | AI2: % | AJ2: CATEGORIA DE FRAGILIDAD | AK2: SPER | AL2: Idef | AM2: Ivel | AN2: Ipro | AO2: I | AQ2: Valor | AR2: zonificacion | AS2: SPER | AT2: VALOR | AU2: ZONIFICACION | AV2: P(Hi) | AW2: V | AX2: RIESGO ESPECIFICO | AY2: ZONIFICACION | AZ2: E | BA2: RIESGO PERSONAS | BB2: ZONIFICACION | BC2: RIESGO TOTAL | BD2: ZONIFICACION
X3: Elementos verticales | Y3: Elementos Horizontales | Z3: Elementos no estructurales
A4: 1 | B4: MZ_A12 | C4: 75° 8'49.75"O | D4: 4°27'13.09"N | E4: Medianera | F4: 1 | G4: 72 | H4: Incompleta | I4: Autoconstruccion | J4: Alcantarillado, Acueducto, Electricidad, Gas, Telefono | K4: 3 | L4: Zapatas (No identificada) | M4: Placa maciza de concreto | N4: Mamposteria no reforzada | O4: Estructura de madera y teja | P4: Despues de 1998 (2004) | Q4: No realizadas | R4: Baja o inexistente | S4: baja o inexistente | T4: D | U4: Deficiencias constructivas | V4: No presenta daños | W4: No se ha inundado | X4: Ninguno | Y4: Ninguno | Z4: Ninguno | AA4: Conexiones aguas servidas mpio | AB4: No se han reparado | AC4: 2 | AD4: 0.7 | AE4: 0.05 | AF4: 0.25 | AG4: 0.5 | AH4: =1-(1-AD4)*(1-AE4)*(1-AF4)*(1-AG4) -> 0.893125 | AI4: =AH4*100 -> 89.3125 | AJ4: Alta | AK4: =(AH4)^3.2 -> 0.6964969 | AL4: 0.1 | AM4: 0.1 | AN4: 0 | AO4: =1-(1-AL4)*(1-AM4)*(1-AN4) -> 0.19 | AP4: =1-AH4 -> 0.106875 | AQ4: =IF(AO4<=AP4,0.5*((AO4/AP4)^2),1-0.5*(((1-AO4)/AH4)^2)) -> 0.58874087 | AR4: Alta | AS4: =1-AK4 -> 0.3035031 | AT4: =IF(AO4<=AS4,0.5*((AO4/AS4)^2),1-0.5*(((1-AO4)/AH4)^2)) -> 0.19595256 | AU4: Baja | AV4: 0.00045 | AW4: =AQ4 -> 0.58874087 | AX4: =AV4*AW4 -> 0.00026493339 | AY4: Medio | AZ4: =K4 -> 3 | BA4: =AV4*AW4*AZ4 -> 0.00079480018 | BB4: Bajo | BC4: =AX4+BA4 -> 0.0010597336 | BD4: Bajo
A5: 2 | B5: MZ_A13 | C5: 75° 8'49.96"O | D5: 4°27'13.19"N | E5: Medianera | F5: 1 | G5: 78 | H5: Incompleta | I5: Autoconstruccion | J5: Alcantarillado, Acueducto, Electricidad, Gas, Telefono | K5: 5 | L5: Zapatas (No identificada); placa de cimentacion | M5: No Aplica | N5: Mamposteria no reforzada | O5: Estructura de madera y teja | P5: Despues de 1998 (2004) | Q5: No realizadas | R5: Baja o inexistente | S5: baja o inexistente | T5: D | U5: Ninguna | V5: No presenta daños | W5: No se ha inundado | X5: Ninguno | Y5: Ninguno | Z5: Ninguno | AA5: Conexiones aguas servidas mpio | AB5: No hay daños | AC5: 2 | AD5: 0.7 | AE5: 0.05 | AF5: 0 | AG5: 0.5 | AH5: =1-(1-AD5)*(1-AE5)*(1-AF5)*(1-AG5) -> 0.8575 | AI5: =AH5*100 -> 85.75 | AJ5: Alta | AK5: =(AH5)^3.2 -> 0.61143347 | AL5: 0.1 | AM5: 0.1 | AN5: 0 | AO5: =1-(1-AL5)*(1-AM5)*(1-AN5) -> 0.19 | AP5: =1-AH5 -> 0.1425 | AQ5: =IF(AO5<=AP5,0.5*((AO5/AP5)^2),1-0.5*(((1-AO5)/AH5)^2)) -> 0.55385936 | AR5: Alta | AS5: =1-AK5 -> 0.38856653 | AT5: =IF(AO5<=AS5,0.5*((AO5/AS5)^2),1-0.5*(((1-AO5)/AH5)^2)) -> 0.11954914 | AU5: Baja | AV5: 0.00089 | AW5: =AQ5 -> 0.55385936 | AX5: =AV5*AW5 -> 0.00049293483 | AY5: Medio | AZ5: =K5 -> 5 | BA5: =AV5*AW5*AZ5 -> 0.0024646742 | BB5: Bajo | BC5: =AX5+BA5 -> 0.002957609 | BD5: Medio
A6: 3 | B6: MZ_A14 | C6: 75° 8'49.96"O | D6: 4°27'13.03"N | E6: Medianera | F6: 1 | G6: 52 | H6: En construccion | I6: Autoconstruccion | J6: Alcantarillado, Acueducto, Electricidad, Gas, Telefono | K6: 7 | L6: Zapatas (No identificada); placa de cimentacion | M6: No Aplica | N6: Mamposteria no reforzada | O6: Estructura de madera y teja | P6: Despues de 1998 | Q6: No realizadas | R6: Alta | S6: Alta | T6: D | U6: Deficiencias constructivas | V6: No presenta daños | W6: No se ha inundado | X6: Ninguno | Y6: Ninguno | Z6: Ninguno | AA6: Conexiones aguas servidas mpio | AB6: No se han reparado | AC6: 2 | AD6: 0.7 | AE6: 0.05 | AF6: 0.25 | AG6: 0.5 | AH6: =1-(1-AD6)*(1-AE6)*(1-AF6)*(1-AG6) -> 0.893125 | AI6: =AH6*100 -> 89.3125 | AJ6: Alta | AK6: =(AH6)^3.2 -> 0.6964969 | AL6: 0.1 | AM6: 0.1 | AN6: 0 | AO6: =1-(1-AL6)*(1-AM6)*(1-AN6) -> 0.19 | AP6: =1-AH6 -> 0.106875 | AQ6: =IF(AO6<=AP6,0.5*((AO6/AP6)^2),1-0.5*(((1-AO6)/AH6)^2)) -> 0.58874087 | AR6: Alta | AS6: =1-AK6 -> 0.3035031 | AT6: =IF(AO6<=AS6,0.5*((AO6/AS6)^2),1-0.5*(((1-AO6)/AH6)^2)) -> 0.19595256 | AU6: Baja | AV6: 0.00089 | AW6: =AQ6 -> 0.58874087 | AX6: =AV6*AW6 -> 0.00052397938 | AY6: Medio | AZ6: =K6 -> 7 | BA6: =AV6*AW6*AZ6 -> 0.0036678556 | BB6: Bajo | BC6: =AX6+BA6 -> 0.004191835 | BD6: Medio
A7: 4 | B7: MZ_A15 | C7: 75° 8'50.00"O | D7: 4°27'12.89"N | E7: Medianera | F7: 1 | G7: 29.7 | H7: Incompleta | I7: Autoconstruccion | J7: Acueducto, Electricidad | K7: 2 | L7: Zapatas (No identificada); placa de cimentacion | M7: No Aplica | N7: Mamposteria no reforzada | O7: Estructura de madera y teja | P7: Despues de 1998 (2017) | Q7: No realizadas | R7: Alta | S7: Alta | T7: D | U7: Deficiencias constructivas | V7: No presenta daños | W7: No se ha inundado | X7: Ninguno | Y7: Ninguno | Z7: Ninguno | AA7: conexiones Improvisadas | AB7: No se han reparado | AC7: 2 | AD7: 0.7 | AE7: 0.05 | AF7: 0.25 | AG7: 0.5 | AH7: =1-(1-AD7)*(1-AE7)*(1-AF7)*(1-AG7) -> 0.893125 | AI7: =AH7*100 -> 89.3125 | AJ7: Alta | AK7: =(AH7)^3.2 -> 0.6964969 | AL7: 0.1 | AM7: 0.1 | AN7: 0 | AO7: =1-(1-AL7)*(1-AM7)*(1-AN7) -> 0.19 | AP7: =1-AH7 -> 0.106875 | AQ7: =IF(AO7<=AP7,0.5*((AO7/AP7)^2),1-0.5*(((1-AO7)/AH7)^2)) -> 0.58874087 | AR7: Alta | AS7: =1-AK7 -> 0.3035031 | AT7: =IF(AO7<=AS7,0.5*((AO7/AS7)^2),1-0.5*(((1-AO7)/AH7)^2)) -> 0.19595256 | AU7: Baja | AV7: 0.00089 | AW7: =AQ7 -> 0.58874087 | AX7: =AV7*AW7 -> 0.00052397938 | AY7: Medio | AZ7: =K7 -> 2 | BA7: =AV7*AW7*AZ7 -> 0.0010479588 | BB7: Bajo | BC7: =AX7+BA7 -> 0.0015719381 | BD7: Bajo
A8: 5 | B8: MZ_A16 | C8: 75° 8'49.84"O | D8: 4°27'12.99"N | E8: Medianera | F8: 1 | G8: 35 | H8: Incompleta | I8: Autoconstruccion | J8: Acueducto, Electricidad | K8: 3 | L8: Zapatas (No identificada); placa de cimentacion | M8: No Aplica | N8: Mamposteria no reforzada | O8: Estructura de madera y teja | P8: Despues de 1998 (2017) | Q8: No realizadas | R8: Alta | S8: Alta | T8: D | U8: Deficiencias constructivas | V8: No presenta daños | W8: No se ha inundado | X8: Ninguno | Y8: Ninguno | Z8: Ninguno | AA8: conexiones Improvisadas | AB8: No se han reparado | AC8: 2 | AD8: 0.7 | AE8: 0.05 | AF8: 0.25 | AG8: 0.5 | AH8: =1-(1-AD8)*(1-AE8)*(1-AF8)*(1-AG8) -> 0.893125 | AI8: =AH8*100 -> 89.3125 | AJ8: Alta | AK8: =(AH8)^3.2 -> 0.6964969 | AL8: 0.1 | AM8: 0.1 | AN8: 0 | AO8: =1-(1-AL8)*(1-AM8)*(1-AN8) -> 0.19 | AP8: =1-AH8 -> 0.106875 | AQ8: =IF(AO8<=AP8,0.5*((AO8/AP8)^2),1-0.5*(((1-AO8)/AH8)^2)) -> 0.58874087 | AR8: Alta | AS8: =1-AK8 -> 0.3035031 | AT8: =IF(AO8<=AS8,0.5*((AO8/AS8)^2),1-0.5*(((1-AO8)/AH8)^2)) -> 0.19595256 | AU8: Baja | AV8: 0.00089 | AW8: =AQ8 -> 0.58874087 | AX8: =AV8*AW8 -> 0.00052397938 | AY8: Medio | AZ8: =K8 -> 3 | BA8: =AV8*AW8*AZ8 -> 0.0015719381 | BB8: Bajo | BC8: =AX8+BA8 -> 0.0020959175 | BD8: Bajo
A9: 6 | B9: MZ_A17 | C9: 75° 8'49.93"O | D9: 4°27'13.00"N | E9: Medianera | F9: 1 | G9: 60 | H9: Incompleta | I9: Autoconstruccion | J9: Acueducto, Electricidad | K9: 3 | L9: Zapatas (No identificada); placa de cimentacion | M9: No Aplica | N9: Mamposteria no reforzada | O9: Estructura de madera y teja | P9: Despues de 1998 (2017) | Q9: No realizadas | R9: Alta | S9: Alta | T9: D | U9: Movimiento en masa, Inundaciones | V9: No presenta daños | W9: No se ha inundado | X9: Ninguno | Y9: Ninguno | Z9: Ninguno | AA9: conexiones Improvisadas | AB9: No se han reparado | AC9: 2 | AD9: 0.7 | AE9: 0.05 | AF9: 0.5 | AG9: 0.5 | AH9: =1-(1-AD9)*(1-AE9)*(1-AF9)*(1-AG9) -> 0.92875 | AI9: =AH9*100 -> 92.875 | AJ9: Muy alta | AK9: =(AH9)^3.2 -> 0.78936205 | AL9: 0.1 | AM9: 0.1 | AN9: 0 | AO9: =1-(1-AL9)*(1-AM9)*(1-AN9) -> 0.19 | AP9: =1-AH9 -> 0.07125 | AQ9: =IF(AO9<=AP9,0.5*((AO9/AP9)^2),1-0.5*(((1-AO9)/AH9)^2)) -> 0.61968593 | AR9: Alta | AS9: =1-AK9 -> 0.21063795 | AT9: =IF(AO9<=AS9,0.5*((AO9/AS9)^2),1-0.5*(((1-AO9)/AH9)^2)) -> 0.40682158 | AU9: Media | AV9: 0.00089 | AW9: =AQ9 -> 0.61968593 | AX9: =AV9*AW9 -> 0.00055152048 | AY9: Medio | AZ9: =K9 -> 3 | BA9: =AV9*AW9*AZ9 -> 0.0016545614 | BB9: Bajo | BC9: =AX9+BA9 -> 0.0022060819 | BD9: Bajo
A10: 7 | B10: MZ_A_INVASION_1 | C10: 75° 8'51.25"O | D10: 4°27'13.34"N | E10: Esquinera | F10: 2 | G10: 54 | H10: Incompleta | I10: Autoconstruccion | J10: Acueducto, Electricidad | K10: 3 | L10: No identificada | M10: Entremado en madera | N10: Mamposteria no reforzada | O10: Estructura de madera y teja (lote) | P10: Sin Informacion | Q10: No realizadas | R10: Alta | S10: Alta | T10: D | U10: Movimiento en masa, Deficiencias constructivas | V10: No presenta daños | W10: No se ha inundado | X10: Ninguno | Y10: Ninguno | Z10: Ninguno | AA10: conexiones Improvisadas | AB10: No hay daños | AC10: 2 | AD10: 0.7 | AE10: 0.6 | AF10: 0.5 | AG10: 0.5 | AH10: =1-(1-AD10)*(1-AE10)*(1-AF10)*(1-AG10) -> 0.97 | AI10: =AH10*100 -> 97 | AJ10: Muy alta | AK10: =(AH10)^3.2 -> 0.90713004 | AL10: 0.1 | AM10: 0.1 | AN10: 0 | AO10: =1-(1-AL10)*(1-AM10)*(1-AN10) -> 0.19 | AP10: =1-AH10 -> 0.03 | AQ10: =IF(AO10<=AP10,0.5*((AO10/AP10)^2),1-0.5*(((1-AO10)/AH10)^2)) -> 0.65134446 | AR10: Alta | AS10: =1-AK10 -> 0.092869959 | AT10: =IF(AO10<=AS10,0.5*((AO10/AS10)^2),1-0.5*(((1-AO10)/AH10)^2)) -> 0.65134446 | AU10: Alta | AV10: 0.00089 | AW10: =AQ10 -> 0.65134446 | AX10: =AV10*AW10 -> 0.00057969657 | AY10: Medio | AZ10: =K10 -> 3 | BA10: =AV10*AW10*AZ10 -> 0.0017390897 | BB10: Bajo | BC10: =AX10+BA10 -> 0.0023187863 | BD10: Bajo
A11: 8 | B11: MZ_A_INVASION_2 | C11: 75° 8'50.69"O | D11: 4°27'13.78"N | E11: Medianera | F11: 1 | G11: Sin informacion | H11: Incompleta | I11: Autoconstruccion | J11: Acueducto, Electricidad, Gas | K11: 3 | L11: No identificada | M11: No identificado | N11: No identificado | O11: No identificada | P11: Sin Informacion | Q11: Sin informacion | R11: Alta | S11: Alta | T11: N/A | U11: No identificado | V11: No identificado | W11: No se ha inundado | X11: No identificado | Y11: No identificado | Z11: No identificado | AA11: conexiones Improvisadas | AB11: No identificado | AC11: 2 | AD11: 0.7 | AE11: 0.05 | AF11: 0.25 | AG11: 0.5 | AH11: =1-(1-AD11)*(1-AE11)*(1-AF11)*(1-AG11) -> 0.893125 | AI11: =AH11*100 -> 89.3125 | AJ11: Alta | AK11: =(AH11)^3.2 -> 0.6964969 | AL11: 0.1 | AM11: 0.1 | AN11: 0 | AO11: =1-(1-AL11)*(1-AM11)*(1-AN11) -> 0.19 | AP11: =1-AH11 -> 0.106875 | AQ11: =IF(AO11<=AP11,0.5*((AO11/AP11)^2),1-0.5*(((1-AO11)/AH11)^2)) -> 0.58874087 | AR11: Alta | AS11: =1-AK11 -> 0.3035031 | AT11: =IF(AO11<=AS11,0.5*((AO11/AS11)^2),1-0.5*(((1-AO11)/AH11)^2)) -> 0.19595256 | AU11: Baja | AV11: 0.00089 | AW11: =AQ11 -> 0.58874087 | AX11: =AV11*AW11 -> 0.00052397938 | AY11: Medio | AZ11: =K11 -> 3 | BA11: =AV11*AW11*AZ11 -> 0.0015719381 | BB11: Bajo | BC11: =AX11+BA11 -> 0.0020959175 | BD11: Bajo
A12: 9 | B12: MZ_E4 | C12: 75° 8'52.39"O | D12: 4°27'15.01"N | E12: Esquinera | F12: 2 | G12: 78 | H12: Incompleta | I12: Autoconstruccion | J12: Alcantarillado, Acueducto, Electricidad, Gas, Telefono | K12: 8 | L12: Zapatas (No identificada); placa de cimentacion | M12: Lamina colaborante | N12: Sistema combinado en concreto reforzado | O12: Estructura metalica y teja | P12: Despues de 1998 (2003) | Q12: En altura | R12: Baja o inexistente | S12: baja o inexistente | T12: B | U12: Ninguna | V12: No presenta daños | W12: No se ha inundado | X12: Ninguno | Y12: Ninguno | Z12: Ninguno | AA12: Conexiones aguas servidas mpio | AB12: No se han reparado | AC12: 1 | AD12: 0.3 | AE12: 0.6 | AF12: 0 | AG12: 0.3 | AH12: =1-(1-AD12)*(1-AE12)*(1-AF12)*(1-AG12) -> 0.804 | AI12: =AH12*100 -> 80.4 | AJ12: Alta | AK12: =(AH12)^3.2 -> 0.4975301 | AL12: 0.1 | AM12: 0.1 | AN12: 0 | AO12: =1-(1-AL12)*(1-AM12)*(1-AN12) -> 0.19 | AP12: =1-AH12 -> 0.196 | AQ12: =IF(AO12<=AP12,0.5*((AO12/AP12)^2),1-0.5*(((1-AO12)/AH12)^2)) -> 0.46985631 | AR12: Media | AS12: =1-AK12 -> 0.5024699 | AT12: =IF(AO12<=AS12,0.5*((AO12/AS12)^2),1-0.5*(((1-AO12)/AH12)^2)) -> 0.071491942 | AU12: Baja | AV12: 0.00045 | AW12: =AQ12 -> 0.46985631 | AX12: =AV12*AW12 -> 0.00021143534 | AY12: Bajo | AZ12: =K12 -> 8 | BA12: =AV12*AW12*AZ12 -> 0.0016914827 | BB12: Bajo | BC12: =AX12+BA12 -> 0.0019029181 | BD12: Bajo
A13: 10 | B13: MZ_F1 | C13: 75° 8'52.94"O | D13: 4°27'15.20"N | E13: Esquinera | F13: 1 | G13: 60 | H13: Incompleta | I13: Autoconstruccion | J13: Acueducto, Electricidad, Gas, Telefono | K13: 8 | L13: Zapatas (No identificada); placa de cimentacion | M13: No Aplica | N13: Mamposteria no reforzada | O13: Estructura de madera y teja | P13: Despues de 1998 (2002) | Q13: No realizadas | R13: Alta | S13: Alta | T13: D | U13: Movimiento en masa, Deficiencias constructivas | V13: No presenta daños | W13: No se ha inundado | X13: Ninguno | Y13: Ninguno | Z13: Ninguno | AA13: conexiones Improvisadas | AB13: No hay daños | AC13: 1 | AD13: 0.7 | AE13: 0.05 | AF13: 0.5 | AG13: 0.5 | AH13: =1-(1-AD13)*(1-AE13)*(1-AF13)*(1-AG13) -> 0.92875 | AI13: =AH13*100 -> 92.875 | AJ13: Muy alta | AK13: =(AH13)^3.2 -> 0.78936205 | AL13: 0.1 | AM13: 0.1 | AN13: 0 | AO13: =1-(1-AL13)*(1-AM13)*(1-AN13) -> 0.19 | AP13: =1-AH13 -> 0.07125 | AQ13: =IF(AO13<=AP13,0.5*((AO13/AP13)^2),1-0.5*(((1-AO13)/AH13)^2)) -> 0.61968593 | AR13: Alta | AS13: =1-AK13 -> 0.21063795 | AT13: =IF(AO13<=AS13,0.5*((AO13/AS13)^2),1-0.5*(((1-AO13)/AH13)^2)) -> 0.40682158 | AU13: Media | AV13: 0.0017 | AW13: =AQ13 -> 0.61968593 | AX13: =AV13*AW13 -> 0.0010534661 | AY13: Alta | AZ13: =K13 -> 8 | BA13: =AV13*AW13*AZ13 -> 0.0084277287 | BB13: Bajo | BC13: =AX13+BA13 -> 0.0094811948 | BD13: Medio
A14: 11 | B14: MZ_G1 | C14: 75° 8'52.66"O | D14: 4°27'15.24"N | E14: Esquinera | F14: 1 | G14: 72 | H14: Incompleta | I14: Autoconstruccion | J14: Alcantarillado, Acueducto, Electricidad, Gas, Telefono | K14: 2 | L14: Zapatas (No identificada); placa de cimentacion | M14: No Aplica | N14: Mamposteria no reforzada | O14: Estructura de madera y teja | P14: 2021 | Q14: No realizadas | R14: Baja o inexistente | S14: Media | T14: D | U14: Deficiencias constructivas | V14: Fisuras | W14: No se ha inundado | X14: Moderado | Y14: Ninguno | Z14: Ninguno | AA14: Conexiones aguas servidas mpio | AB14: No hay daños | AC14: 1 | AD14: 0.7 | AE14: 0.05 | AF14: 0.25 | AG14: 0.3 | AH14: =1-(1-AD14)*(1-AE14)*(1-AF14)*(1-AG14) -> 0.850375 | AI14: =AH14*100 -> 85.0375 | AJ14: Alta | AK14: =(AH14)^3.2 -> 0.59532422 | AL14: 0.1 | AM14: 0.1 | AN14: 0 | AO14: =1-(1-AL14)*(1-AM14)*(1-AN14) -> 0.19 | AP14: =1-AH14 -> 0.149625 | AQ14: =IF(AO14<=AP14,0.5*((AO14/AP14)^2),1-0.5*(((1-AO14)/AH14)^2)) -> 0.54635192 | AR14: Alta | AS14: =1-AK14 -> 0.40467578 | AT14: =IF(AO14<=AS14,0.5*((AO14/AS14)^2),1-0.5*(((1-AO14)/AH14)^2)) -> 0.1102206 | AU14: Baja | AV14: 0.00045 | AW14: =AQ14 -> 0.54635192 | AX14: =AV14*AW14 -> 0.00024585837 | AY14: Bajo | AZ14: =K14 -> 2 | BA14: =AV14*AW14*AZ14 -> 0.00049171673 | BB14: Bajo | BC14: =AX14+BA14 -> 0.0007375751 | BD14: Muy bajo
A15: 12 | B15: MZ_G3 | C15: 75° 8'53.09"O | D15: 4°27'15.32"N | E15: Esquinera | F15: 1 | G15: 72 | H15: Incompleta | I15: Autoconstruccion | J15: Acueducto, Gas, Telefono | K15: 3 | L15: Zapatas (No identificada); placa de cimentacion | M15: No Aplica | N15: Mamposteria no reforzada | O15: Estructura metalica y teja | P15: 2006 | Q15: No realizadas | R15: Media | S15: baja o inexistente | T15: D | U15: Asentamientos, Deficiencias constructivas | V15: No presenta daños | W15: No se ha inundado | X15: Ninguno | Y15: Leve | Z15: Ninguno | AA15: conexiones Improvisadas | AB15: No hay daños | AC15: 1 | AD15: 0.7 | AE15: 0.05 | AF15: 0.25 | AG15: 0.3 | AH15: =1-(1-AD15)*(1-AE15)*(1-AF15)*(1-AG15) -> 0.850375 | AI15: =AH15*100 -> 85.0375 | AJ15: Alta | AK15: =(AH15)^3.2 -> 0.59532422 | AL15: 0.1 | AM15: 0.1 | AN15: 0 | AO15: =1-(1-AL15)*(1-AM15)*(1-AN15) -> 0.19 | AP15: =1-AH15 -> 0.149625 | AQ15: =IF(AO15<=AP15,0.5*((AO15/AP15)^2),1-0.5*(((1-AO15)/AH15)^2)) -> 0.54635192 | AR15: Alta | AS15: =1-AK15 -> 0.40467578 | AT15: =IF(AO15<=AS15,0.5*((AO15/AS15)^2),1-0.5*(((1-AO15)/AH15)^2)) -> 0.1102206 | AU15: Baja | AV15: 0.00045 | AW15: =AQ15 -> 0.54635192 | AX15: =AV15*AW15 -> 0.00024585837 | AY15: Bajo | AZ15: =K15 -> 3 | BA15: =AV15*AW15*AZ15 -> 0.0007375751 | BB15: Bajo | BC15: =AX15+BA15 -> 0.00098343346 | BD15: Bajo
A16: 13 | B16: MZ_H2 | C16: 75° 8'53.50"O | D16: 4°27'14.86"N | E16: Medianera | F16: 1 | G16: 72 | H16: Incompleta | I16: Autoconstruccion | J16: Alcantarillado, Acueducto, Electricidad, Gas, Telefono | K16: 3 | L16: Zapatas, Vigas corridas,No identificada; placa de cimentacion | M16: No Aplica | N16: Mamposteria reforzada | O16: Estructura metalica y teja | P16: 2000 | Q16: En extension | R16: Baja o inexistente | S16: baja o inexistente | T16: C | U16: Ninguna | V16: No presenta daños | W16: No se ha inundado | X16: Ninguno | Y16: Ninguno | Z16: Ninguno | AA16: Conexiones aguas servidas mpio | AB16: No hay daños | AC16: 1 | AD16: 0.5 | AE16: 0.05 | AF16: 0 | AG16: 0.3 | AH16: =1-(1-AD16)*(1-AE16)*(1-AF16)*(1-AG16) -> 0.6675 | AI16: =AH16*100 -> 66.75 | AJ16: Media | AK16: =(AH16)^3.2 -> 0.27431153 | AL16: 0.1 | AM16: 0.1 | AN16: 0 | AO16: =1-(1-AL16)*(1-AM16)*(1-AN16) -> 0.19 | AP16: =1-AH16 -> 0.3325 | AQ16: =IF(AO16<=AP16,0.5*((AO16/AP16)^2),1-0.5*(((1-AO16)/AH16)^2)) -> 0.16326531 | AR16: Baja | AS16: =1-AK16 -> 0.72568847 | AT16: =IF(AO16<=AS16,0.5*((AO16/AS16)^2),1-0.5*(((1-AO16)/AH16)^2)) -> 0.034274945 | AU16: Baja | AV16: 0.00045 | AW16: =AQ16 -> 0.16326531 | AX16: =AV16*AW16 -> 7.3469388e-05 | AY16: Bajo | AZ16: =K16 -> 3 | BA16: =AV16*AW16*AZ16 -> 0.00022040816 | BB16: Bajo | BC16: =AX16+BA16 -> 0.00029387755 | BD16: Muy bajo
A17: 14 | B17: MZ_H3 | C17: 75° 8'53.51"O | D17: 4°27'14.81"N | E17: Medianera | F17: 1 | G17: 72 | H17: Incompleta | I17: Autoconstruccion | J17: Alcantarillado, Acueducto, Electricidad, Gas, Telefono | K17: 3 | L17: Zapatas, Vigas corridas,No identificada; placa de cimentacion | M17: No Aplica | N17: Mamposteria reforzada | O17: Estructura metalica y teja | P17: 2004 | Q17: Profundidad | R17: Baja o inexistente | S17: baja o inexistente | T17: C | U17: Ninguna | V17: No presenta daños | W17: No se ha inundado | X17: Ninguno | Y17: Ninguno | Z17: Ninguno | AA17: Conexiones aguas servidas mpio | AB17: No hay daños | AC17: 1 | AD17: 0.5 | AE17: 0.05 | AF17: 0 | AG17: 0.3 | AH17: =1-(1-AD17)*(1-AE17)*(1-AF17)*(1-AG17) -> 0.6675 | AI17: =AH17*100 -> 66.75 | AJ17: Media | AK17: =(AH17)^3.2 -> 0.27431153 | AL17: 0.1 | AM17: 0.1 | AN17: 0 | AO17: =1-(1-AL17)*(1-AM17)*(1-AN17) -> 0.19 | AP17: =1-AH17 -> 0.3325 | AQ17: =IF(AO17<=AP17,0.5*((AO17/AP17)^2),1-0.5*(((1-AO17)/AH17)^2)) -> 0.16326531 | AR17: Baja | AS17: =1-AK17 -> 0.72568847 | AT17: =IF(AO17<=AS17,0.5*((AO17/AS17)^2),1-0.5*(((1-AO17)/AH17)^2)) -> 0.034274945 | AU17: Baja | AV17: 0.00045 | AW17: =AQ17 -> 0.16326531 | AX17: =AV17*AW17 -> 7.3469388e-05 | AY17: Bajo | AZ17: =K17 -> 3 | BA17: =AV17*AW17*AZ17 -> 0.00022040816 | BB17: Bajo | BC17: =AX17+BA17 -> 0.00029387755 | BD17: Muy bajo
A18: 15 | B18: MZ_H4 | C18: 75° 8'53.61"O | D18: 4°27'14.65"N | E18: Esquinera | F18: 1 | G18: 72 | H18: Incompleta | I18: Autoconstruccion | J18: Alcantarillado, Acueducto, Electricidad, Gas, Telefono | K18: 2 | L18: Zapatas, Vigas corridas,No identificada; placa de cimentacion | M18: No Aplica | N18: Mamposteria reforzada | O18: Estructura metalica y teja | P18: 2014 | Q18: No realizadas | R18: Media | S18: baja o inexistente | T18: C | U18: Ninguna | V18: No presenta daños | W18: No se ha inundado | X18: Ninguno | Y18: Ninguno | Z18: Ninguno | AA18: Conexiones aguas servidas mpio | AB18: No hay daños | AC18: 1 | AD18: 0.5 | AE18: 0.05 | AF18: 0 | AG18: 0.3 | AH18: =1-(1-AD18)*(1-AE18)*(1-AF18)*(1-AG18) -> 0.6675 | AI18: =AH18*100 -> 66.75 | AJ18: Media | AK18: =(AH18)^3.2 -> 0.27431153 | AL18: 0.1 | AM18: 0.1 | AN18: 0 | AO18: =1-(1-AL18)*(1-AM18)*(1-AN18) -> 0.19 | AP18: =1-AH18 -> 0.3325 | AQ18: =IF(AO18<=AP18,0.5*((AO18/AP18)^2),1-0.5*(((1-AO18)/AH18)^2)) -> 0.16326531 | AR18: Baja | AS18: =1-AK18 -> 0.72568847 | AT18: =IF(AO18<=AS18,0.5*((AO18/AS18)^2),1-0.5*(((1-AO18)/AH18)^2)) -> 0.034274945 | AU18: Baja | AV18: 0.00045 | AW18: =AQ18 -> 0.16326531 | AX18: =AV18*AW18 -> 7.3469388e-05 | AY18: Bajo | AZ18: =K18 -> 2 | BA18: =AV18*AW18*AZ18 -> 0.00014693878 | BB18: Bajo | BC18: =AX18+BA18 -> 0.00022040816 | BD18: Muy bajo
A19: 16 | B19: MZ_H5 | C19: 75° 8'54.61"O | D19: 4°27'14.73"N | E19: Esquinera | F19: 2 | G19: 72 | H19: Incompleta | I19: Autoconstruccion | J19: Alcantarillado, Acueducto, Electricidad, Gas, Telefono | K19: 0 | L19: Zapatas (No identificada); placa de cimentacion | M19: Placa maciza de concreto | N19: Mamposteria reforzada | O19: No aplica | P19: Despues de 1998 | Q19: En altura | R19: Baja o inexistente | S19: baja o inexistente | T19: C | U19: Ninguna | V19: No presenta daños | W19: No se ha inundado | X19: Ninguno | Y19: Ninguno | Z19: Ninguno | AA19: Conexiones aguas servidas mpio | AB19: No hay daños | AC19: 1 | AD19: 0.5 | AE19: 0.6 | AF19: 0 | AG19: 0.5 | AH19: =1-(1-AD19)*(1-AE19)*(1-AF19)*(1-AG19) -> 0.9 | AI19: =AH19*100 -> 90 | AJ19: Muy Alta | AK19: =(AH19)^3.2 -> 0.71379916 | AL19: 0.1 | AM19: 0.1 | AN19: 0 | AO19: =1-(1-AL19)*(1-AM19)*(1-AN19) -> 0.19 | AP19: =1-AH19 -> 0.1 | AQ19: =IF(AO19<=AP19,0.5*((AO19/AP19)^2),1-0.5*(((1-AO19)/AH19)^2)) -> 0.595 | AR19: Alta | AS19: =1-AK19 -> 0.28620084 | AT19: =IF(AO19<=AS19,0.5*((AO19/AS19)^2),1-0.5*(((1-AO19)/AH19)^2)) -> 0.22036133 | AU19: Baja | AV19: 0.00045 | AW19: =AQ19 -> 0.595 | AX19: =AV19*AW19 -> 0.00026775 | AY19: Bajo | AZ19: 0 | BA19: =AV19*AW19*AZ19 -> 0 | BB19: Bajo | BC19: =AX19+BA19 -> 0.00026775 | BD19: Muy bajo
A20: 17 | B20: MZ_I1 | C20: 75° 8'53.43"O | D20: 4°27'15.55"N | E20: Esquinera | F20: 2 | G20: 72 | H20: Incompleta | I20: Autoconstruccion | J20: Alcantarillado, Acueducto, Electricidad, Gas, Telefono | K20: 3 | L20: Zapatas (No identificada); placa de cimentacion | M20: Placa aligerada del concreto | N20: Porticos en concreto reforzado | O20: Estructura metalica y teja | P20: 2003 | Q20: En altura | R20: Baja o inexistente | S20: baja o inexistente | T20: C | U20: Ninguna | V20: No presenta daños | W20: No se ha inundado | X20: Ninguno | Y20: Ninguno | Z20: Ninguno | AA20: Conexiones aguas servidas mpio | AB20: No hay daños | AC20: 1 | AD20: 0.5 | AE20: 0.05 | AF20: 0 | AG20: 0.5 | AH20: =1-(1-AD20)*(1-AE20)*(1-AF20)*(1-AG20) -> 0.7625 | AI20: =AH20*100 -> 76.25 | AJ20: Media-Alta | AK20: =(AH20)^3.2 -> 0.41992092 | AL20: 0.1 | AM20: 0.1 | AN20: 0 | AO20: =1-(1-AL20)*(1-AM20)*(1-AN20) -> 0.19 | AP20: =1-AH20 -> 0.2375 | AQ20: =IF(AO20<=AP20,0.5*((AO20/AP20)^2),1-0.5*(((1-AO20)/AH20)^2)) -> 0.32 | AR20: Media | AS20: =1-AK20 -> 0.58007908 | AT20: =IF(AO20<=AS20,0.5*((AO20/AS20)^2),1-0.5*(((1-AO20)/AH20)^2)) -> 0.053641733 | AU20: Baja | AV20: 0.00045 | AW20: =AQ20 -> 0.32 | AX20: =AV20*AW20 -> 0.000144 | AY20: Bajo | AZ20: =K20 -> 3 | BA20: =AV20*AW20*AZ20 -> 0.000432 | BB20: Bajo | BC20: =AX20+BA20 -> 0.000576 | BD20: Muy bajo
A21: 18 | B21: MZ_I2 | C21: 75° 8'53.69"O | D21: 4°27'15.41"N | E21: Medianera | F21: 1 | G21: 72 | H21: Incompleta | I21: Autoconstruccion | J21: Acueducto, Electricidad, Gas, Telefono | K21: 1 | L21: Zapatas (No identificada); placa de cimentacion | M21: No Aplica | N21: Mamposteria no reforzada | O21: Estructura metalica y teja | P21: 2008 | Q21: No realizadas | R21: Media | S21: Media | T21: D | U21: Ninguna | V21: No presenta daños | W21: No se ha inundado | X21: Ninguno | Y21: Ninguno | Z21: Ninguno | AA21: Conexiones aguas servidas mpio | AB21: No se han reparado, No hay daños | AC21: 1 | AD21: 0.5 | AE21: 0.05 | AF21: 0 | AG21: 0.5 | AH21: =1-(1-AD21)*(1-AE21)*(1-AF21)*(1-AG21) -> 0.7625 | AI21: =AH21*100 -> 76.25 | AJ21: Media-Alta | AK21: =(AH21)^3.2 -> 0.41992092 | AL21: 0.1 | AM21: 0.1 | AN21: 0 | AO21: =1-(1-AL21)*(1-AM21)*(1-AN21) -> 0.19 | AP21: =1-AH21 -> 0.2375 | AQ21: =IF(AO21<=AP21,0.5*((AO21/AP21)^2),1-0.5*(((1-AO21)/AH21)^2)) -> 0.32 | AR21: Media | AS21: =1-AK21 -> 0.58007908 | AT21: =IF(AO21<=AS21,0.5*((AO21/AS21)^2),1-0.5*(((1-AO21)/AH21)^2)) -> 0.053641733 | AU21: Baja | AV21: 0.00045 | AW21: =AQ21 -> 0.32 | AX21: =AV21*AW21 -> 0.000144 | AY21: Bajo | AZ21: =K21 -> 1 | BA21: =AV21*AW21*AZ21 -> 0.000144 | BB21: Bajo | BC21: =AX21+BA21 -> 0.000288 | BD21: Muy bajo
A22: 19 | B22: MZ_J6 | C22: 75° 8'54.81"O | D22: 4°27'14.81"N | E22: Medianera | F22: 1 | G22: 72 | H22: Incompleta | I22: Autoconstruccion | J22: Alcantarillado, Acueducto, Electricidad, Gas | K22: 4 | L22: No identificada | M22: No Aplica | N22: Mamposteria reforzada | O22: Estructura metalica y teja | P22: Sin Informacion | Q22: Profundidad | R22: Media | S22: Media | T22: C | U22: Ninguna | V22: No presenta daños | W22: No se ha inundado | X22: Ninguno | Y22: Ninguno | Z22: Ninguno | AA22: Conexiones aguas servidas mpio | AB22: No hay daños | AC22: 1 | AD22: 0.5 | AE22: 0.05 | AF22: 0 | AG22: 0.5 | AH22: =1-(1-AD22)*(1-AE22)*(1-AF22)*(1-AG22) -> 0.7625 | AI22: =AH22*100 -> 76.25 | AJ22: Media-Alta | AK22: =(AH22)^3.2 -> 0.41992092 | AL22: 0.1 | AM22: 0.1 | AN22: 0 | AO22: =1-(1-AL22)*(1-AM22)*(1-AN22) -> 0.19 | AP22: =1-AH22 -> 0.2375 | AQ22: =IF(AO22<=AP22,0.5*((AO22/AP22)^2),1-0.5*(((1-AO22)/AH22)^2)) -> 0.32 | AR22: Media | AS22: =1-AK22 -> 0.58007908 | AT22: =IF(AO22<=AS22,0.5*((AO22/AS22)^2),1-0.5*(((1-AO22)/AH22)^2)) -> 0.053641733 | AU22: Baja | AV22: 0.00045 | AW22: =AQ22 -> 0.32 | AX22: =AV22*AW22 -> 0.000144 | AY22: Bajo | AZ22: =K22 -> 4 | BA22: =AV22*AW22*AZ22 -> 0.000576 | BB22: Bajo | BC22: =AX22+BA22 -> 0.00072 | BD22: Muy bajo
A23: 20 | B23: MZ_K2 | C23: 75° 8'54.60"O | D23: 4°27'15.85"N | E23: Medianera | F23: 3 | G23: 72 | H23: Incompleta | I23: Autoconstruccion | J23: Alcantarillado, Acueducto, Electricidad, Gas, Telefono | K23: 3 | L23: No identificada | M23: Placa aligerada del concreto | N23: Porticos en concreto reforzado | O23: Estructura metalica y teja | P23: Sin Informacion | Q23: En altura | R23: Media | S23: Media | T23: N/A | U23: Ninguna | V23: No presenta daños | W23: No se ha inundado | X23: Ninguno | Y23: Ninguno | Z23: Ninguno | AA23: Conexiones aguas servidas mpio | AB23: No hay daños | AC23: 1 | AD23: 0.7 | AE23: 0.6 | AF23: 0 | AG23: 0.5 | AH23: =1-(1-AD23)*(1-AE23)*(1-AF23)*(1-AG23) -> 0.94 | AI23: =AH23*100 -> 94 | AJ23: Muy Alta | AK23: =(AH23)^3.2 -> 0.82036879 | AL23: 0.1 | AM23: 0.1 | AN23: 0 | AO23: =1-(1-AL23)*(1-AM23)*(1-AN23) -> 0.19 | AP23: =1-AH23 -> 0.06 | AQ23: =IF(AO23<=AP23,0.5*((AO23/AP23)^2),1-0.5*(((1-AO23)/AH23)^2)) -> 0.62873472 | AR23: Alta | AS23: =1-AK23 -> 0.17963121 | AT23: =IF(AO23<=AS23,0.5*((AO23/AS23)^2),1-0.5*(((1-AO23)/AH23)^2)) -> 0.62873472 | AU23: Alta | AV23: 0.00045 | AW23: =AQ23 -> 0.62873472 | AX23: =AV23*AW23 -> 0.00028293062 | AY23: Medio | AZ23: =K23 -> 3 | BA23: =AV23*AW23*AZ23 -> 0.00084879187 | BB23: Bajo | BC23: =AX23+BA23 -> 0.0011317225 | BD23: Bajo
A24: 21 | B24: MZ_K3 | C24: 75° 8'54.76"O | D24: 4°27'15.89"N | E24: Medianera | F24: 3 | G24: 72 | H24: Completa | I24: Autoconstruccion | J24: Alcantarillado, Acueducto, Electricidad, Gas, Telefono | K24: 8 | L24: Zapatas (No identificada); placa de cimentacion | M24: Placa maciza de concreto | N24: Porticos en concreto reforzado, Mamposteria reforzada | O24: Estructura metalica y teja | P24: 2006 | Q24: En altura | R24: Baja o inexistente | S24: baja o inexistente | T24: C | U24: Deficiencias constructivas | V24: No presenta daños | W24: No se ha inundado | X24: Ninguno | Y24: Ninguno | Z24: Ninguno | AA24: Conexiones aguas servidas mpio | AB24: No hay daños | AC24: 1 | AD24: 0.5 | AE24: 0.6 | AF24: 0.25 | AG24: 0.5 | AH24: =1-(1-AD24)*(1-AE24)*(1-AF24)*(1-AG24) -> 0.925 | AI24: =AH24*100 -> 92.5 | AJ24: Muy Alta | AK24: =(AH24)^3.2 -> 0.77920825 | AL24: 0.1 | AM24: 0.1 | AN24: 0 | AO24: =1-(1-AL24)*(1-AM24)*(1-AN24) -> 0.19 | AP24: =1-AH24 -> 0.075 | AQ24: =IF(AO24<=AP24,0.5*((AO24/AP24)^2),1-0.5*(((1-AO24)/AH24)^2)) -> 0.61659606 | AR24: Alta | AS24: =1-AK24 -> 0.22079175 | AT24: =IF(AO24<=AS24,0.5*((AO24/AS24)^2),1-0.5*(((1-AO24)/AH24)^2)) -> 0.37026405 | AU24: Media | AV24: 0.00045 | AW24: =AQ24 -> 0.61659606 | AX24: =AV24*AW24 -> 0.00027746822 | AY24: Medio | AZ24: =K24 -> 8 | BA24: =AV24*AW24*AZ24 -> 0.0022197458 | BB24: Bajo | BC24: =AX24+BA24 -> 0.002497214 | BD24: Bajo
A25: 22 | B25: MZ_M1 | C25: 75° 8'55.42"O | D25: 4°27'15.90"N | E25: Esquinera | F25: 2 | G25: 36 | H25: Completa | I25: Autoconstruccion | J25: Alcantarillado, Acueducto, Electricidad, Gas | K25: 2 | L25: Zapatas, Vigas corridas,No identificada; placa de cimentacion | M25: Placa aligerada del concreto | N25: Mamposteria reforzada | O25: Estructura metalica y teja | P25: 2002 | Q25: No realizadas | R25: Baja o inexistente | S25: baja o inexistente | T25: C | U25: Deficiencias constructivas | V25: No presenta daños | W25: No se ha inundado | X25: Leve | Y25: Ninguno | Z25: Ninguno | AA25: Conexiones aguas servidas mpio | AB25: No hay daños | AC25: 1 | AD25: 0.5 | AE25: 0.6 | AF25: 0.25 | AG25: 0.3 | AH25: =1-(1-AD25)*(1-AE25)*(1-AF25)*(1-AG25) -> 0.895 | AI25: =AH25*100 -> 89.5 | AJ25: Alta | AK25: =(AH25)^3.2 -> 0.70118677 | AL25: 0.1 | AM25: 0.1 | AN25: 0 | AO25: =1-(1-AL25)*(1-AM25)*(1-AN25) -> 0.19 | AP25: =1-AH25 -> 0.105 | AQ25: =IF(AO25<=AP25,0.5*((AO25/AP25)^2),1-0.5*(((1-AO25)/AH25)^2)) -> 0.59046222 | AR25: Alta | AS25: =1-AK25 -> 0.29881323 | AT25: =IF(AO25<=AS25,0.5*((AO25/AS25)^2),1-0.5*(((1-AO25)/AH25)^2)) -> 0.20215178 | AU25: Baja | AV25: 0.00045 | AW25: =AQ25 -> 0.59046222 | AX25: =AV25*AW25 -> 0.000265708 | AY25: Medio | AZ25: =K25 -> 2 | BA25: =AV25*AW25*AZ25 -> 0.000531416 | BB25: Bajo | BC25: =AX25+BA25 -> 0.000797124 | BD25: Muy bajo
A26: 23 | B26: MZ_M1A | C26: 75° 8'55.60"O | D26: 4°27'16.11"N | E26: Medianera | F26: 2 | G26: 36 | H26: Incompleta | I26: Autoconstruccion | J26: Alcantarillado, Acueducto, Electricidad, Gas | K26: 2 | L26: Zapatas, Vigas corridas,No identificada; placa de cimentacion | M26: Placa aligerada del concreto | N26: Mamposteria no reforzada | O26: No aplica | P26: 2024 | Q26: En altura | R26: Baja o inexistente | S26: baja o inexistente | T26: C | U26: Deficiencias constructivas | V26: Humedas | W26: No se ha inundado | X26: Ninguno | Y26: Ninguno | Z26: Ninguno | AA26: Conexiones aguas servidas mpio | AB26: No hay daños | AC26: 1 | AD26: 0.5 | AE26: 0.6 | AF26: 0.25 | AG26: 0.7 | AH26: =1-(1-AD26)*(1-AE26)*(1-AF26)*(1-AG26) -> 0.955 | AI26: =AH26*100 -> 95.5 | AJ26: Muy Alta | AK26: =(AH26)^3.2 -> 0.86299999 | AL26: 0.1 | AM26: 0.1 | AN26: 0 | AO26: =1-(1-AL26)*(1-AM26)*(1-AN26) -> 0.19 | AP26: =1-AH26 -> 0.045 | AQ26: =IF(AO26<=AP26,0.5*((AO26/AP26)^2),1-0.5*(((1-AO26)/AH26)^2)) -> 0.64030591 | AR26: Alta | AS26: =1-AK26 -> 0.13700001 | AT26: =IF(AO26<=AS26,0.5*((AO26/AS26)^2),1-0.5*(((1-AO26)/AH26)^2)) -> 0.64030591 | AU26: Alta | AV26: 0.00045 | AW26: =AQ26 -> 0.64030591 | AX26: =AV26*AW26 -> 0.00028813766 | AY26: Medio | AZ26: =K26 -> 2 | BA26: =AV26*AW26*AZ26 -> 0.00057627532 | BB26: Bajo | BC26: =AX26+BA26 -> 0.00086441298 | BD26: Muy bajo
A27: 24 | B27: MZ_M2 | C27: 75° 8'55.49"O | D27: 4°27'16.21"N | E27: Medianera | F27: 1 | G27: 72 | H27: Incompleta | I27: Autoconstruccion | J27: Alcantarillado, Acueducto, Electricidad, Gas, Telefono | K27: 4 | L27: Zapatas, Vigas corridas,No identificada; placa de cimentacion | M27: No Aplica | N27: Mamposteria reforzada | O27: Estructura metalica y teja | P27: 2004 | Q27: No realizadas | R27: Baja o inexistente | S27: baja o inexistente | T27: C | U27: Ninguna | V27: Desprendimiento de pintura | W27: No se ha inundado | X27: Ninguno | Y27: Ninguno | Z27: Ninguno | AA27: Conexiones aguas servidas mpio | AB27: No hay daños | AC27: 1 | AD27: 0.5 | AE27: 0.05 | AF27: 0 | AG27: 0.5 | AH27: =1-(1-AD27)*(1-AE27)*(1-AF27)*(1-AG27) -> 0.7625 | AI27: =AH27*100 -> 76.25 | AJ27: Media-Alta | AK27: =(AH27)^3.2 -> 0.41992092 | AL27: 0.1 | AM27: 0.1 | AN27: 0 | AO27: =1-(1-AL27)*(1-AM27)*(1-AN27) -> 0.19 | AP27: =1-AH27 -> 0.2375 | AQ27: =IF(AO27<=AP27,0.5*((AO27/AP27)^2),1-0.5*(((1-AO27)/AH27)^2)) -> 0.32 | AR27: Media | AS27: =1-AK27 -> 0.58007908 | AT27: =IF(AO27<=AS27,0.5*((AO27/AS27)^2),1-0.5*(((1-AO27)/AH27)^2)) -> 0.053641733 | AU27: Baja | AV27: 0.00045 | AW27: =AQ27 -> 0.32 | AX27: =AV27*AW27 -> 0.000144 | AY27: Bajo | AZ27: =K27 -> 4 | BA27: =AV27*AW27*AZ27 -> 0.000576 | BB27: Bajo | BC27: =AX27+BA27 -> 0.00072 | BD27: Muy bajo
A28: 25 | B28: MZ_M3 | C28: 75° 8'55.66"O | D28: 4°27'16.16"N | E28: Medianera | F28: 1 | G28: 82.5 | H28: Incompleta | I28: Autoconstruccion | J28: Alcantarillado, Acueducto, Electricidad, Gas, Telefono | K28: 0 | L28: Placa de cimentacion, No identificada | M28: No Aplica | N28: Portico en concreto reforzado, Mamposteria reforzada | O28: Estructura metalica y teja | P28: Despues de 1998 | Q28: En extension | R28: baja o inexistente | S28: baja o inexistente | T28: C | U28: Ninguna | V28: No presenta daños | W28: No se ha inundado | X28: Ninguno | Y28: Ninguno | Z28: Ninguno | AA28: conexiones improvisadas | AB28: No hay daños | AC28: 1 | AD28: 0.5 | AE28: 0.05 | AF28: 0 | AG28: 0.5 | AH28: =1-(1-AD28)*(1-AE28)*(1-AF28)*(1-AG28) -> 0.7625 | AI28: =AH28*100 -> 76.25 | AJ28: Media-Alta | AK28: =(AH28)^3.2 -> 0.41992092 | AL28: 0.1 | AM28: 0.1 | AN28: 0 | AO28: =1-(1-AL28)*(1-AM28)*(1-AN28) -> 0.19 | AP28: =1-AH28 -> 0.2375 | AQ28: =IF(AO28<=AP28,0.5*((AO28/AP28)^2),1-0.5*(((1-AO28)/AH28)^2)) -> 0.32 | AR28: Media | AS28: =1-AK28 -> 0.58007908 | AT28: =IF(AO28<=AS28,0.5*((AO28/AS28)^2),1-0.5*(((1-AO28)/AH28)^2)) -> 0.053641733 | AU28: Baja | AV28: 0.00045 | AW28: =AQ28 -> 0.32 | AX28: =AV28*AW28 -> 0.000144 | AY28: Bajo | AZ28: 0 | BA28: =AV28*AW28*AZ28 -> 0 | BB28: Bajo | BC28: =AX28+BA28 -> 0.000144 | BD28: Muy bajo
A29: 26 | B29: MZ_M4 | C29: 75° 8'56.01"O | D29: 4°27'16.38"N | E29: Esquinera | F29: 2 | G29: 72 | H29: Incompleta | I29: Autoconstruccion | J29: Alcantarillado, Acueducto, Electricidad, Gas, Telefono | K29: 6 | L29: no identificada | M29: Placa maciza de concreto | N29: Mamposteria reforzada | O29: Estructura metalica y teja | P29: Despues de 1999 | Q29: No realizadas | R29: Baja o inexistente | S29: baja o inexistente | T29: C | U29: Ninguna | V29: No presenta daños | W29: no se ha inundado | X29: Ninguno | Y29: Ninguno | Z29: Ninguno | AA29: Conexiones aguas servidas mpio | AB29: No hay daños | AC29: 1 | AD29: 0.5 | AE29: 0.6 | AF29: 0 | AG29: 0.5 | AH29: =1-(1-AD29)*(1-AE29)*(1-AF29)*(1-AG29) -> 0.9 | AI29: =AH29*100 -> 90 | AJ29: Muy Alta | AK29: =(AH29)^3.2 -> 0.71379916 | AL29: 0.1 | AM29: 0.1 | AN29: 0 | AO29: =1-(1-AL29)*(1-AM29)*(1-AN29) -> 0.19 | AP29: =1-AH29 -> 0.1 | AQ29: =IF(AO29<=AP29,0.5*((AO29/AP29)^2),1-0.5*(((1-AO29)/AH29)^2)) -> 0.595 | AR29: Alta | AS29: =1-AK29 -> 0.28620084 | AT29: =IF(AO29<=AS29,0.5*((AO29/AS29)^2),1-0.5*(((1-AO29)/AH29)^2)) -> 0.22036133 | AU29: Baja | AV29: 0.00045 | AW29: =AQ29 -> 0.595 | AX29: =AV29*AW29 -> 0.00026775 | AY29: Medio | AZ29: =K29 -> 6 | BA29: =AV29*AW29*AZ29 -> 0.0016065 | BB29: Bajo | BC29: =AX29+BA29 -> 0.00187425 | BD29: Bajo
A30: 27 | B30: MZ_O1 | C30: 75° 8'56.11"O | D30: 4°27'16.59"N | E30: Esquinera | F30: 1 | G30: 72 | H30: Incompleta | I30: Autoconstruccion | J30: Alcantarillado, Acueducto, Electricidad, Gas, Telefono | K30: 4 | L30: no identificada | M30: No Aplica | N30: Mamposteria reforzada | O30: Estructura metalica y teja | P30: Despues de 1999 | Q30: No realizadas | R30: baja o inexistente | S30: baja o inexistente | T30: C | U30: Deficiencias constructivas | V30: No presenta daños | W30: No se ha inundado | X30: Leve | Y30: Ninguno | Z30: Ninguno | AA30: Conexiones aguas servidas mpio | AB30: No hay daños | AC30: 1 | AD30: 0.5 | AE30: 0.05 | AF30: 0.25 | AG30: 0.5 | AH30: =1-(1-AD30)*(1-AE30)*(1-AF30)*(1-AG30) -> 0.821875 | AI30: =AH30*100 -> 82.1875 | AJ30: Alta | AK30: =(AH30)^3.2 -> 0.53379987 | AL30: 0.1 | AM30: 0.1 | AN30: 0 | AO30: =1-(1-AL30)*(1-AM30)*(1-AN30) -> 0.19 | AP30: =1-AH30 -> 0.178125 | AQ30: =IF(AO30<=AP30,0.5*((AO30/AP30)^2),1-0.5*(((1-AO30)/AH30)^2)) -> 0.51434429 | AR30: Alta | AS30: =1-AK30 -> 0.46620013 | AT30: =IF(AO30<=AS30,0.5*((AO30/AS30)^2),1-0.5*(((1-AO30)/AH30)^2)) -> 0.083048621 | AU30: Baja | AV30: 0.00045 | AW30: =AQ30 -> 0.51434429 | AX30: =AV30*AW30 -> 0.00023145493 | AY30: Bajo | AZ30: =K30 -> 4 | BA30: =AV30*AW30*AZ30 -> 0.00092581972 | BB30: Bajo | BC30: =AX30+BA30 -> 0.0011572746 | BD30: Bajo
A31: 28 | B31: MZ_O2 | C31: 75° 8'56.46"O | D31: 4°27'16.68"N | E31: Medianera | F31: 1 | G31: 72 | H31: Completa | I31: Autoconstruccion | J31: Alcantarillado, Acueducto, Electricidad, Gas, Telefono | K31: 3 | L31: Zapatas, Vigas corridas,No identificada; placa de cimentacion | M31: No Aplica | N31: Mamposteria no reforzada | O31: Estructura metalica y teja | P31: 2020 | Q31: En extension | R31: Baja o inexistente | S31: baja o inexistente | T31: C | U31: Deficiencias constructivas | V31: No presenta daños | W31: No se ha inundado | X31: Leve | Y31: Ninguno | Z31: Ninguno | AA31: Conexiones aguas servidas mpio | AB31: No hay daños | AC31: 1 | AD31: 0.5 | AE31: 0.05 | AF31: 0.25 | AG31: 0.1 | AH31: =1-(1-AD31)*(1-AE31)*(1-AF31)*(1-AG31) -> 0.679375 | AI31: =AH31*100 -> 67.9375 | AJ31: Media | AK31: =(AH31)^3.2 -> 0.29023554 | AL31: 0.1 | AM31: 0.1 | AN31: 0 | AO31: =1-(1-AL31)*(1-AM31)*(1-AN31) -> 0.19 | AP31: =1-AH31 -> 0.320625 | AQ31: =IF(AO31<=AP31,0.5*((AO31/AP31)^2),1-0.5*(((1-AO31)/AH31)^2)) -> 0.17558299 | AR31: Baja | AS31: =1-AK31 -> 0.70976446 | AT31: =IF(AO31<=AS31,0.5*((AO31/AS31)^2),1-0.5*(((1-AO31)/AH31)^2)) -> 0.035830157 | AU31: Baja | AV31: 0.00045 | AW31: =AQ31 -> 0.17558299 | AX31: =AV31*AW31 -> 7.9012346e-05 | AY31: Bajo | AZ31: =K31 -> 3 | BA31: =AV31*AW31*AZ31 -> 0.00023703704 | BB31: Bajo | BC31: =AX31+BA31 -> 0.00031604938 | BD31: Muy bajo
A32: 29 | B32: MZ_O3 | C32: 75° 8'56.74"O | D32: 4°27'16.80"N | E32: Medianera | F32: 2 | G32: 72 | H32: Incompleta | I32: Autoconstruccion | J32: Alcantarillado, Acueducto, Electricidad, Gas | K32: 3 | L32: Zapatas, Vigas corridas,No identificada; placa de cimentacion | M32: Placa aligerada del concreto | N32: Portico en concreto reforzado, Mamposteria reforzada | O32: Estructura metalica y teja | P32: 2011 | Q32: En extension | R32: baja o inexistente | S32: baja o inexistente | T32: C | U32: Deficiencias constructivas | V32: No presenta daños | W32: No se ha inundado | X32: Ninguno | Y32: Ninguno | Z32: Ninguno | AA32: Conexiones aguas servidas mpio | AB32: No hay daños | AC32: 1 | AD32: 0.5 | AE32: 0.6 | AF32: 0.25 | AG32: 0.3 | AH32: =1-(1-AD32)*(1-AE32)*(1-AF32)*(1-AG32) -> 0.895 | AI32: =AH32*100 -> 89.5 | AJ32: Alta | AK32: =(AH32)^3.2 -> 0.70118677 | AL32: 0.1 | AM32: 0.1 | AN32: 0 | AO32: =1-(1-AL32)*(1-AM32)*(1-AN32) -> 0.19 | AP32: =1-AH32 -> 0.105 | AQ32: =IF(AO32<=AP32,0.5*((AO32/AP32)^2),1-0.5*(((1-AO32)/AH32)^2)) -> 0.59046222 | AR32: Alta | AS32: =1-AK32 -> 0.29881323 | AT32: =IF(AO32<=AS32,0.5*((AO32/AS32)^2),1-0.5*(((1-AO32)/AH32)^2)) -> 0.20215178 | AU32: Baja | AV32: 0.00045 | AW32: =AQ32 -> 0.59046222 | AX32: =AV32*AW32 -> 0.000265708 | AY32: Medio | AZ32: =K32 -> 3 | BA32: =AV32*AW32*AZ32 -> 0.000797124 | BB32: Bajo | BC32: =AX32+BA32 -> 0.001062832 | BD32: Bajo
A33: 30 | B33: MZ_O4 | C33: 75° 8'57.00"O | D33: 4°27'17.07"N | E33: Esquinera | F33: 2 | G33: 72 | H33: Incompleta | I33: Autoconstruccion | J33: Alcantarillado, Acueducto, Electricidad, Gas | K33: 3 | L33: Zapatas, Vigas corridas,No identificada; placa de cimentacion | M33: Placa maciza de concreto | N33: Sistema combinado en concreto reforzado | O33: Estructura metalica y teja | P33: 2002 | Q33: En extension | R33: Baja o inexistente | S33: baja o inexistente | T33: C | U33: Deficiencias constructivas | V33: No presenta daños | W33: No se ha inundado | X33: Ninguno | Y33: Ninguno | Z33: Ninguno | AA33: Conexiones aguas servidas mpio | AB33: No hay daños | AC33: 1 | AD33: 0.5 | AE33: 0.6 | AF33: 0.25 | AG33: 0.3 | AH33: =1-(1-AD33)*(1-AE33)*(1-AF33)*(1-AG33) -> 0.895 | AI33: =AH33*100 -> 89.5 | AJ33: Alta | AK33: =(AH33)^3.2 -> 0.70118677 | AL33: 0.1 | AM33: 0.1 | AN33: 0 | AO33: =1-(1-AL33)*(1-AM33)*(1-AN33) -> 0.19 | AP33: =1-AH33 -> 0.105 | AQ33: =IF(AO33<=AP33,0.5*((AO33/AP33)^2),1-0.5*(((1-AO33)/AH33)^2)) -> 0.59046222 | AR33: Alta | AS33: =1-AK33 -> 0.29881323 | AT33: =IF(AO33<=AS33,0.5*((AO33/AS33)^2),1-0.5*(((1-AO33)/AH33)^2)) -> 0.20215178 | AU33: Baja | AV33: 0.00045 | AW33: =AQ33 -> 0.59046222 | AX33: =AV33*AW33 -> 0.000265708 | AY33: Medio | AZ33: =K33 -> 3 | BA33: =AV33*AW33*AZ33 -> 0.000797124 | BB33: Bajo | BC33: =AX33+BA33 -> 0.001062832 | BD33: Bajo
A34: 31 | B34: MZ_K1- | C34: 75° 8'54.43"O | D34: 4°27'15.74"N | E34: Esquinera | F34: 2 | G34: 72 | H34: Incompleta | I34: Autoconstruccion | J34: Alcantarillado, Acueducto, Electricidad | K34: 4 | L34: No identificada | M34: Placa aligerada del concreto | N34: Portico en concreto reforzado | O34: No aplica | P34: Despues de 1999 | Q34: En extension | R34: Baja o inexistente | S34: baja o inexistente | T34: B | U34: No identificado | V34: No identificado | W34: No se ha inundado | X34: Ninguno | Y34: Ninguno | Z34: Ninguno | AA34: Conexiones aguas servidas mpio | AB34: No identificado | AC34: 1 | AD34: 0.3 | AE34: 0.6 | AF34: 0.25 | AG34: 0.3 | AH34: =1-(1-AD34)*(1-AE34)*(1-AF34)*(1-AG34) -> 0.853 | AI34: =AH34*100 -> 85.3 | AJ34: Alta | AK34: =(AH34)^3.2 -> 0.60122482 | AL34: 0.1 | AM34: 0.1 | AN34: 0 | AO34: =1-(1-AL34)*(1-AM34)*(1-AN34) -> 0.19 | AP34: =1-AH34 -> 0.147 | AQ34: =IF(AO34<=AP34,0.5*((AO34/AP34)^2),1-0.5*(((1-AO34)/AH34)^2)) -> 0.54913972 | AR34: Alta | AS34: =1-AK34 -> 0.39877518 | AT34: =IF(AO34<=AS34,0.5*((AO34/AS34)^2),1-0.5*(((1-AO34)/AH34)^2)) -> 0.11350656 | AU34: Baja | AV34: 0.00045 | AW34: =AQ34 -> 0.54913972 | AX34: =AV34*AW34 -> 0.00024711287 | AY34: Bajo | AZ34: =K34 -> 4 | BA34: =AV34*AW34*AZ34 -> 0.00098845149 | BB34: Bajo | BC34: =AX34+BA34 -> 0.0012355644 | BD34: Bajo
A35: 32 | B35: MZ_G2- | C35: 75° 8'52.79"O | D35: 4°27'15.35"N | E35: Medianera | F35: 1 | G35: 72 | H35: Incompleta | I35: Autoconstruccion | J35: Alcantarillado, Acueducto, Electricidad | K35: 4 | L35: No identificada | M35: No Aplica | N35: No identificado | O35: No identificada | P35: Despues de 1999 | Q35: En extension | R35: Baja o inexistente | S35: baja o inexistente | T35: N/A | U35: No identificado | V35: No identificado | W35: No se ha inundado | X35: No identificado | Y35: No identificado | Z35: No identificado | AA35: Conexiones aguas servidas mpio | AB35: No identificado | AC35: 1 | AD35: 0.7 | AE35: 0.05 | AF35: 0.25 | AG35: 0.5 | AH35: =1-(1-AD35)*(1-AE35)*(1-AF35)*(1-AG35) -> 0.893125 | AI35: =AH35*100 -> 89.3125 | AJ35: Alta | AK35: =(AH35)^3.2 -> 0.6964969 | AL35: 0.1 | AM35: 0.1 | AN35: 0 | AO35: =1-(1-AL35)*(1-AM35)*(1-AN35) -> 0.19 | AP35: =1-AH35 -> 0.106875 | AQ35: =IF(AO35<=AP35,0.5*((AO35/AP35)^2),1-0.5*(((1-AO35)/AH35)^2)) -> 0.58874087 | AR35: Alta | AS35: =1-AK35 -> 0.3035031 | AT35: =IF(AO35<=AS35,0.5*((AO35/AS35)^2),1-0.5*(((1-AO35)/AH35)^2)) -> 0.19595256 | AU35: Baja | AV35: 0.00045 | AW35: =AQ35 -> 0.58874087 | AX35: =AV35*AW35 -> 0.00026493339 | AY35: Medio | AZ35: =K35 -> 4 | BA35: =AV35*AW35*AZ35 -> 0.0010597336 | BB35: Bajo | BC35: =AX35+BA35 -> 0.001324667 | BD35: Bajo
A36: 33 | B36: MZ_H1- | C36: 75° 8'53.15"O | D36: 4°27'15.24"N | E36: Esquinera | F36: 4 | G36: 72 | H36: Completa | I36: Autoconstruccion | J36: Alcantarillado, Acueducto, Electricidad | K36: 0 | L36: Placa de cimentacion | M36: Placa maciza de concreto | N36: Mamposteria reforzada | O36: Estructura metalica y teja | P36: Despues de 1999 | Q36: En extension | R36: baja o inexistente | S36: baja o inexistente | T36: C | U36: No identificado | V36: No identificado | W36: No se ha inundado | X36: No identificado | Y36: No identificado | Z36: No identificado | AA36: Conexiones aguas servidas mpio | AB36: No identificado | AC36: 1 | AD36: 0.5 | AE36: 0.9 | AF36: 0.25 | AG36: 0.5 | AH36: =1-(1-AD36)*(1-AE36)*(1-AF36)*(1-AG36) -> 0.98125 | AI36: =AH36*100 -> 98.125 | AJ36: Muy Alta | AK36: =(AH36)^3.2 -> 0.94122823 | AL36: 0.1 | AM36: 0.1 | AN36: 0 | AO36: =1-(1-AL36)*(1-AM36)*(1-AN36) -> 0.19 | AP36: =1-AH36 -> 0.01875 | AQ36: =IF(AO36<=AP36,0.5*((AO36/AP36)^2),1-0.5*(((1-AO36)/AH36)^2)) -> 0.65929328 | AR36: Alta | AS36: =1-AK36 -> 0.058771773 | AT36: =IF(AO36<=AS36,0.5*((AO36/AS36)^2),1-0.5*(((1-AO36)/AH36)^2)) -> 0.65929328 | AU36: Alta | AV36: 0.00045 | AW36: =AQ36 -> 0.65929328 | AX36: =AV36*AW36 -> 0.00029668197 | AY36: Medio | AZ36: =K36 -> 0 | BA36: =AV36*AW36*AZ36 -> 0 | BB36: Bajo | BC36: =AX36+BA36 -> 0.00029668197 | BD36: Bajo
A37: 34 | B37: MZ_J5- | C37: 75° 8'54.66"O | D37: 4°27'14.50"N | E37: Medianera | F37: 1 | G37: 72 | H37: Incompleta | I37: Autoconstruccion | J37: Alcantarillado, Acueducto, Electricidad | K37: 4 | L37: No identificada | M37: No Aplica | N37: No identificado | O37: No identificada | P37: Despues de 1999 | Q37: No realizadas | R37: Baja o inexistente | S37: baja o inexistente | T37: N/A | U37: Deficiencias constructivas | V37: No identificado | W37: No se ha inundado | X37: No identificado | Y37: No identificado | Z37: No identificado | AA37: Conexiones aguas servidas mpio | AB37: No identificado | AC37: 1 | AD37: 0.7 | AE37: 0.05 | AF37: 0.25 | AG37: 0.5 | AH37: =1-(1-AD37)*(1-AE37)*(1-AF37)*(1-AG37) -> 0.893125 | AI37: =AH37*100 -> 89.3125 | AJ37: Alta | AK37: =(AH37)^3.2 -> 0.6964969 | AL37: 0.1 | AM37: 0.1 | AN37: 0 | AO37: =1-(1-AL37)*(1-AM37)*(1-AN37) -> 0.19 | AP37: =1-AH37 -> 0.106875 | AQ37: =IF(AO37<=AP37,0.5*((AO37/AP37)^2),1-0.5*(((1-AO37)/AH37)^2)) -> 0.58874087 | AR37: Alta | AS37: =1-AK37 -> 0.3035031 | AT37: =IF(AO37<=AS37,0.5*((AO37/AS37)^2),1-0.5*(((1-AO37)/AH37)^2)) -> 0.19595256 | AU37: Baja | AV37: 0.00045 | AW37: =AQ37 -> 0.58874087 | AX37: =AV37*AW37 -> 0.00026493339 | AY37: Medio | AZ37: =K37 -> 4 | BA37: =AV37*AW37*AZ37 -> 0.0010597336 | BB37: Bajo | BC37: =AX37+BA37 -> 0.001324667 | BD37: Bajo
A38: 35 | B38: MZ_H_LOTE | C38: 75° 8'54.07"O | D38: 4°27'14.38"N | E38: No hay edificacion | F38: N/A | G38: N/A | H38: No construido | I38: N/A | J38: N/A | K38: 0 | L38: N/A | M38: N/A | N38: N/A | O38: N/A | P38: N/A | Q38: N/A | R38: N/A | S38: N/A | T38: N/A | U38: N/A | V38: N/A | W38: N/A | X38: N/A | Y38: N/A | Z38: N/A | AA38: N/A | AB38: N/A | AC38: N/A | AD38: 0.7 | AE38: 0.6 | AF38: 0.25 | AG38: 0.5 | AH38: =1-(1-AD38)*(1-AE38)*(1-AF38)*(1-AG38) -> 0.955 | AI38: =AH38*100 -> 95.5 | AJ38: Muy Alta | AK38: =(AH38)^3.2 -> 0.86299999 | AL38: 0.1 | AM38: 0.1 | AN38: 0 | AO38: =1-(1-AL38)*(1-AM38)*(1-AN38) -> 0.19 | AP38: =1-AH38 -> 0.045 | AQ38: =IF(AO38<=AP38,0.5*((AO38/AP38)^2),1-0.5*(((1-AO38)/AH38)^2)) -> 0.64030591 | AR38: Alta | AS38: =1-AK38 -> 0.13700001 | AT38: =IF(AO38<=AS38,0.5*((AO38/AS38)^2),1-0.5*(((1-AO38)/AH38)^2)) -> 0.64030591 | AU38: Alta | AV38: 0.00045 | AW38: =AQ38 -> 0.64030591 | AX38: =AV38*AW38 -> 0.00028813766 | AY38: Medio | AZ38: =K38 -> 0 | BA38: =AV38*AW38*AZ38 -> 0 | BB38: Bajo | BC38: =AX38+BA38 -> 0.00028813766 | BD38: Muy bajo
A39: 36 | B39: MZ_K4- | C39: 75° 8'55.05"O | D39: 4°27'16.04"N | E39: Esquinera | F39: 1 | G39: 72 | H39: Incompleta | I39: Autoconstruccion | J39: Alcantarillado, Acueducto, Electricidad | K39: 0 | L39: No identificada | M39: No identificado | N39: No identificado | O39: Estructura metalica y teja | P39: Despues de 1999 | Q39: En extension | R39: Media | S39: Media | T39: N/A | U39: Deficiencias constructivas | V39: Fisuras | W39: No se ha inundado | X39: Moderado | Y39: Ninguno | Z39: Ninguno | AA39: Conexiones aguas servidas mpio | AB39: No identificado | AC39: 1 | AD39: 0.7 | AE39: 0.05 | AF39: 0.25 | AG39: 0.5 | AH39: =1-(1-AD39)*(1-AE39)*(1-AF39)*(1-AG39) -> 0.893125 | AI39: =AH39*100 -> 89.3125 | AJ39: Alta | AK39: =(AH39)^3.2 -> 0.6964969 | AL39: 0.1 | AM39: 0.1 | AN39: 0 | AO39: =1-(1-AL39)*(1-AM39)*(1-AN39) -> 0.19 | AP39: =1-AH39 -> 0.106875 | AQ39: =IF(AO39<=AP39,0.5*((AO39/AP39)^2),1-0.5*(((1-AO39)/AH39)^2)) -> 0.58874087 | AR39: Alta | AS39: =1-AK39 -> 0.3035031 | AT39: =IF(AO39<=AS39,0.5*((AO39/AS39)^2),1-0.5*(((1-AO39)/AH39)^2)) -> 0.19595256 | AU39: Baja | AV39: 0.00045 | AW39: =AQ39 -> 0.58874087 | AX39: =AV39*AW39 -> 0.00026493339 | AY39: Medio | AZ39: =K39 -> 0 | BA39: =AV39*AW39*AZ39 -> 0 | BB39: Bajo | BC39: =AX39+BA39 -> 0.00026493339 | BD39: Muy bajo

Sheet OBRAS LINEALES
A1: ID | B1: DIRECCION | C1: COORDENADAS | E1: IDENTIFICACION DE LA EDIFICACION | G1: CLASIFICACION DE LA OBRA LINEAL
C2: LONGITUD | D2: LATITUD | E2: LONGITUD (m) | F2: NUMERO | G2: TIPO DE OBRA LINEAL | I2: REDES VIALES | Q2: CAUSA DE DAÑOS PRESENTES | R2: REDES DEL SERVICIO PUBLICO | U2: CAUSA DE DAÑOS PRESENTES
G3: Red vial | H3: Red de servicio publico | I3: Ancho (m) | J3: Tipo de Arteria Vial | K3: tipo de materialde la estructura | L3: Numero de carriles por calzada | M3: Numero de calzadas | N3: Ancho del carril | O3: Ancho de la berma | P3: Ancho de andenes | R3: Red de Acueducto | S3: Red de Alcantarillado | T3: Red electrica
A4: 1 | B4: Av principal | C4: 75° 8'46.37"W | D4: 4°27'14.35"N | E4: 432 | F4: 1 | G4: Arteria vial | H4: Acueducto, Alcantarillado, Gas, Electricidad, comunicacion | I4: 6 | J4: Intermedia (V6-16m) | K4: Pavimento | L4: 1 | M4: 1 | N4: 6 | O4: No hay | P4: 1-1..5 | Q4: Via destapada | R4: Local (1/2"-2") Diametro: | S4: Local<18" Diametro 8" material PVC corrugado | T4: Mediia tension: 5001 diamtro de poste: | U4: Via destapada

Sheet ANALISIS DE DATOS
A1: DIAGNOSTICO DE VULNERABILIDAD PREDIAL | R1: CATEGORIA DE FRAGILIDAD | S1: %
A3: INDICADOR | B3: TOTAL | R3: Alta | S3: 0.893125 | T3: Muy Alta | U3: 10
A4: Total de predios inspeccionados | B4: 36 | R4: Alta | S4: 0.8575 | T4: Alta | U4: 17
A5: Área total construida | B5: 2257 | R5: Alta | S5: 0.893125 | T5: Media | U5: 4
A6: Población expuesta | B6: 101 | R6: Alta | S6: 0.893125 | T6: Media Alta | U6: 5
A7: Promedio de ocupación | B7: 2.9 | R7: Alta | S7: 0.893125
R8: Muy alta | S8: 0.92875
R9: Muy alta | S9: 0.97
R10: Alta | S10: 0.893125
R11: Alta | S11: 0.804
A12: Sistema estructural | B12: Numero de predios | C12: Porcentaje (%) | R12: Muy alta | S12: 0.92875
A13: Mampostería no reforzada | B13: 31 | C13: 88.6 | R13: Alta | S13: 0.850375
A14: Mampostería reforzada | B14: 3 | C14: 8.6 | R14: Alta | S14: 0.850375
A15: Sistema combinado en concreto | B15: 1 | C15: 2.8 | R15: Media | S15: 0.6675
A16: Total | B16: 35 | C16: 100 | R16: Media | S16: 0.6675
R17: Media | S17: 0.6675
R18: Muy Alta | S18: 0.9
R19: Media-Alta | S19: 0.7625
A20: Estado de la Construcción | B20: N° Predios | C20: Calidad Predominante | D20: Porcentaje (%) | R20: Media-Alta | S20: 0.7625
A21: Incompleta | B21: 30 | C21: Autoconstrucción (85.7%) | D21: =(B21*100)/B25 -> 83.333333 | R21: Media-Alta | S21: 0.7625
A22: En construcción | B22: 1 | C22: Autoconstrucción | D22: =(B22*100)/B25 -> 2.7777778 | R22: Muy Alta | S22: 0.94
A23: Terminada | B23: 1 | C23: Autoconstrucción | D23: =(B23*100)/B25 -> 2.7777778 | R23: Muy Alta | S23: 0.925
A24: completa | B24: 4 | D24: =(B24*100)/B25 -> 11.111111
A25: Total | B25: =SUM(B21:B24) -> 36 | R25: Alta | S25: 0.895
R26: Muy Alta | S26: 0.955
A27: CIMENTACION | B27: valor | C27: PORCENTAJE | R27: Media-Alta | S27: 0.7625
A28: Zapatas | B28: 23 | C28: =(B28*100)/B34 -> 40.350877 | R28: Media-Alta | S28: 0.7625
A29: Zapatas y placa de cimentacion | B29: 13 | C29: =(B29*100)/B34 -> 22.807018 | R29: Muy Alta | S29: 0.9
A30: Placa de cimentacion | B30: 1 | C30: =(B30*100)/B34 -> 1.754386 | R30: Alta | S30: 0.821875
A31: Zapatas, vigas y placa de cimentacion | B31: 9 | C31: =(B31*100)/B34 -> 15.789474 | R31: Media | S31: 0.679375
A32: No identificado | B32: 10 | C32: =(B32*100)/B34 -> 17.54386 | R32: Alta | S32: 0.895
A33: N/A | B33: 1 | C33: =(B33*100)/B39 -> 3.2258065 | R33: Alta | S33: 0.895
A34: Total | B34: =SUM(B28:B33) -> 57 | C34: =(B34*100)/B34 -> 100 | R34: Alta | S34: 0.853
R35: Alta | S35: 0.893125
A36: Elementos Expuestos | B36: Ninguno | C36: Leve | D36: Moderado | E36: No identificado | F36: N/A | R36: Muy Alta | S36: 0.98125
A37: elementos verticales | B37: 26 | C37: 3 | D37: 2 | E37: 4 | F37: 1 | R37: Alta | S37: 0.893125
A38: elementos horizontales | B38: 30 | C38: 1 | D38: 0 | E38: 4 | F38: 1 | R38: Muy Alta | S38: 0.955
A39: Elementos no estructurales | B39: 31 | C39: 0 | D39: 0 | E39: 4 | F39: 1 | R39: Alta | S39: 0.893125
A41: SISTEMA ENTRE PISOS | B41: Valor | C41: PORCENTAJE
A42: no aplica | B42: 19 | C42: =(B42*100)/B47 -> 54.285714
...

Sheet FRAGILIDAD
A1: FRAGILIDAD EDIFICACIONES | H1: FRAGILIDAD PERSONAS | J1: Predio | K1: SE | L1: SPER | P1: SEteorico | Q1: Seteotico
A2: STIP | B2: SALT | C2: SCON | D2: SED | E2: SE | F2: % | G2: CATEGORIA DE FRAGILIDAD | H2: SPER | J2: 1 | K2: 0.893125 | L2: 0.6964969 | P2: 0 | Q2: =(P2)^3.2 -> 0
J3: 2 | K3: 0.8575 | L3: 0.61143347 | P3: =P2+(1/35) -> 0.028571429 | Q3: =(P3)^3.2 -> 1.1454661e-05
A4: 0.7 | B4: 0.05 | C4: 0.25 | D4: 0.5 | E4: =1-(1-A4)*(1-B4)*(1-C4)*(1-D4) -> 0.893125 | F4: =E4*100 -> 89.3125 | G4: Alta | H4: =(E4)^3.2 -> 0.6964969 | J4: 3 | K4: 0.893125 | L4: 0.6964969 | P4: =P3+(1/35) -> 0.057142857 | Q4: =(P4)^3.2 -> 0.00010526361
A5: 0.7 | B5: 0.05 | C5: 0 | D5: 0.5 | E5: =1-(1-A5)*(1-B5)*(1-C5)*(1-D5) -> 0.8575 | F5: =E5*100 -> 85.75 | G5: Alta | H5: =(E5)^3.2 -> 0.61143347 | J5: 4 | K5: 0.893125 | L5: 0.6964969 | P5: =P4+(1/35) -> 0.085714286 | Q5: =(P5)^3.2 -> 0.00038527451
A6: 0.7 | B6: 0.05 | C6: 0.25 | D6: 0.5 | E6: =1-(1-A6)*(1-B6)*(1-C6)*(1-D6) -> 0.893125 | F6: =E6*100 -> 89.3125 | G6: Alta | H6: =(E6)^3.2 -> 0.6964969 | J6: 5 | K6: 0.893125 | L6: 0.6964969 | P6: =P5+(1/35) -> 0.11428571 | Q6: =(P6)^3.2 -> 0.00096732905
A7: 0.7 | B7: 0.05 | C7: 0.25 | D7: 0.5 | E7: =1-(1-A7)*(1-B7)*(1-C7)*(1-D7) -> 0.893125 | F7: =E7*100 -> 89.3125 | G7: Alta | H7: =(E7)^3.2 -> 0.6964969 | J7: 6 | K7: 0.92875 | L7: 0.78936205 | P7: =P6+(1/35) -> 0.14285714 | Q7: =(P7)^3.2 -> 0.001975542
A8: 0.7 | B8: 0.05 | C8: 0.25 | D8: 0.5 | E8: =1-(1-A8)*(1-B8)*(1-C8)*(1-D8) -> 0.893125 | F8: =E8*100 -> 89.3125 | G8: Alta | H8: =(E8)^3.2 -> 0.6964969 | J8: 7 | K8: 0.97 | L8: 0.90713004 | P8: =P7+(1/35) -> 0.17142857 | Q8: =(P8)^3.2 -> 0.0035405135
A9: 0.7 | B9: 0.05 | C9: 0.5 | D9: 0.5 | E9: =1-(1-A9)*(1-B9)*(1-C9)*(1-D9) -> 0.92875 | F9: =E9*100 -> 92.875 | G9: Muy alta | H9: =(E9)^3.2 -> 0.78936205 | J9: 8 | K9: 0.893125 | L9: 0.6964969 | P9: =P8+(1/35) -> 0.2 | Q9: =(P9)^3.2 -> 0.0057982373
A10: 0.7 | B10: 0.6 | C10: 0.5 | D10: 0.5 | E10: =1-(1-A10)*(1-B10)*(1-C10)*(1-D10) -> 0.97 | F10: =E10*100 -> 97 | G10: Muy alta | H10: =(E10)^3.2 -> 0.90713004 | J10: 9 | K10: 0.804 | L10: 0.4975301 | P10: =P9+(1/35) -> 0.22857143 | Q10: =(P10)^3.2 -> 0.0088893543
A11: 0.7 | B11: 0.05 | C11: 0.25 | D11: 0.5 | E11: =1-(1-A11)*(1-B11)*(1-C11)*(1-D11) -> 0.893125 | F11: =E11*100 -> 89.3125 | G11: Alta | H11: =(E11)^3.2 -> 0.6964969 | J11: 10 | K11: 0.92875 | L11: 0.78936205 | P11: =P10+(1/35) -> 0.25714286 | Q11: =(P11)^3.2 -> 0.012958606
A12: 0.3 | B12: 0.6 | C12: 0 | D12: 0.3 | E12: =1-(1-A12)*(1-B12)*(1-C12)*(1-D12) -> 0.804 | F12: =E12*100 -> 80.4 | G12: Alta | H12: =(E12)^3.2 -> 0.4975301 | J12: 11 | K12: 0.850375 | L12: 0.59532422 | P12: =P11+(1/35) -> 0.28571429 | Q12: =(P12)^3.2 -> 0.018154415
A13: 0.7 | B13: 0.05 | C13: 0.5 | D13: 0.5 | E13: =1-(1-A13)*(1-B13)*(1-C13)*(1-D13) -> 0.92875 | F13: =E13*100 -> 92.875 | G13: Muy alta | H13: =(E13)^3.2 -> 0.78936205 | J13: 12 | K13: 0.850375 | L13: 0.59532422 | P13: =P12+(1/35) -> 0.31428571 | Q13: =(P13)^3.2 -> 0.02462855
A14: 0.7 | B14: 0.05 | C14: 0.25 | D14: 0.3 | E14: =1-(1-A14)*(1-B14)*(1-C14)*(1-D14) -> 0.850375 | F14: =E14*100 -> 85.0375 | G14: Alta | H14: =(E14)^3.2 -> 0.59532422 | J14: 13 | K14: 0.6675 | L14: 0.27431153 | P14: =P13+(1/35) -> 0.34285714 | Q14: =(P14)^3.2 -> 0.032535857
A15: 0.7 | B15: 0.05 | C15: 0.25 | D15: 0.3 | E15: =1-(1-A15)*(1-B15)*(1-C15)*(1-D15) -> 0.850375 | F15: =E15*100 -> 85.0375 | G15: Alta | H15: =(E15)^3.2 -> 0.59532422 | J15: 14 | K15: 0.6675 | L15: 0.27431153 | P15: =P14+(1/35) -> 0.37142857 | Q15: =(P15)^3.2 -> 0.042034026
... A37: 0.7 | B37: 0.05 | C37: 0.25 | D37: 0.5 | E37: =1-(1-A37)*(1-B37)*(1-C37)*(1-D37) -> 0.893125 | F37: =E37*100 -> 89.3125 | G37: Alta | H37: =(E37)^3.2 -> 0.6964969 | J37: 36 | K37: 0.893125 | L37: 0.6964969 | P37: =P36+(1/35) -> 1 | Q37: =(P37)^3.2 -> 1
A38: 0.7 | B38: 0.6 | C38: 0.25 | D38: 0.5 | E38: =1-(1-A38)*(1-B38)*(1-C38)*(1-D38) -> 0.955 | F38: =E38*100 -> 95.5 | G38: Muy Alta | H38: =(E38)^3.2 -> 0.86299999
A39: 0.7 | B39: 0.05 | C39: 0.25 | D39: 0.5 | E39: =1-(1-A39)*(1-B39)*(1-C39)*(1-D39) -> 0.893125 | F39: =E39*100 -> 89.3125 | G39: Alta | H39: =(E39)^3.2 -> 0.6964969

Sheet VULNERABILIDAD
A1: =EDIFICACIONES!AL1 -> INTENSIDAD | E1: =EDIFICACIONES!AP1 -> 1-Se | F1: =EDIFICACIONES!AQ1 -> VULNERABILIDAD FISICA | I1: =EDIFICACIONES!AT1 -> VULNERABILIDAD PERSONAS | L1: Vulnerabilidad fisica
A2: =EDIFICACIONES!AL2 -> Idef | B2: =EDIFICACIONES!AM2 -> Ivel | C2: =EDIFICACIONES!AN2 -> Ipro | D2: =EDIFICACIONES!AO2 -> I | F2: =EDIFICACIONES!AQ2 -> Valor | G2: =EDIFICACIONES!AR2 -> zonificacion | H2: =EDIFICACIONES!AS2 -> SPER | I2: =EDIFICACIONES!AT2 -> VALOR | J2: =EDIFICACIONES!AU2 -> ZONIFICACION | L2: Alta | M2: 26
L3: Media | M3: 6
A4: =EDIFICACIONES!AL4 -> 0.1 | B4: =EDIFICACIONES!AM4 -> 0.1 | C4: =EDIFICACIONES!AN4 -> 0 | D4: =EDIFICACIONES!AO4 -> 0.19 | E4: =EDIFICACIONES!AP4 -> 0.106875 | F4: =EDIFICACIONES!AQ4 -> 0.58874087 | G4: =EDIFICACIONES!AR4 -> Alta | H4: =EDIFICACIONES!AS4 -> 0.3035031 | ... J4: =EDIFICACIONES!AU4 -> Baja | L4: Baja | M4: 4
A5: =EDIFICACIONES!AL5 -> 0.1 | B5: =EDIFICACIONES!AM5 -> 0.1 | C5: =EDIFICACIONES!AN5 -> 0 | D5: =EDIFICACIONES!AO5 -> 0.19 | E5: =EDIFICACIONES!AP5 -> 0.1425 | F5: =EDIFICACIONES!AQ5 -> 0.55385936 | G5: =EDIFICACIONES!AR5 -> Alta | H5: =EDIFICACIONES!AS5 -> 0.38856653 | ... J5: =EDIFICACIONES!AU5 -> Baja | L5: Vulnerabilidad personas
A6: =EDIFICACIONES!AL6 -> 0.1 | B6: =EDIFICACIONES!AM6 -> 0.1 | C6: =EDIFICACIONES!AN6 -> 0 | D6: =EDIFICACIONES!AO6 -> 0.19 | E6: =EDIFICACIONES!AP6 -> 0.106875 | F6: =EDIFICACIONES!AQ6 -> 0.58874087 | G6: =EDIFICACIONES!AR6 -> Alta | H6: =EDIFICACIONES!AS6 -> 0.3035031 | ... J6: =EDIFICACIONES!AU6 -> Baja | L6: Alta | M6: 5
A7: =EDIFICACIONES!AL7 -> 0.1 | B7: =EDIFICACIONES!AM7 -> 0.1 | C7: =EDIFICACIONES!AN7 -> 0 | D7: =EDIFICACIONES!AO7 -> 0.19 | E7: =EDIFICACIONES!AP7 -> 0.106875 | F7: =EDIFICACIONES!AQ7 -> 0.58874087 | G7: =EDIFICACIONES!AR7 -> Alta | H7: =EDIFICACIONES!AS7 -> 0.3035031 | ... J7: =EDIFICACIONES!AU7 -> Baja | L7: Media | M7: 3
A8: =EDIFICACIONES!AL8 -> 0.1 | B8: =EDIFICACIONES!AM8 -> 0.1 | C8: =EDIFICACIONES!AN8 -> 0 | D8: =EDIFICACIONES!AO8 -> 0.19 | E8: =EDIFICACIONES!AP8 -> 0.106875 | F8: =EDIFICACIONES!AQ8 -> 0.58874087 | G8: =EDIFICACIONES!AR8 -> Alta | H8: =EDIFICACIONES!AS8 -> 0.3035031 | ... J8: =EDIFICACIONES!AU8 -> Baja | L8: Baja | M8: 28
